try {
  let a = 2
}
catch(err) {
 let v = 5
}